[2025-03-02T21:10:33.378+0000] {local_task_job_runner.py:123} INFO - ::group::Pre task execution logs
[2025-03-02T21:10:33.407+0000] {taskinstance.py:2613} INFO - Dependencies all met for dep_context=non-requeueable deps ti=<TaskInstance: execute_entities.extract_and_load_omie_entities.extract_and_load_ListarMovimentos manual__2025-03-02T21:10:13.514914+00:00 [queued]>
[2025-03-02T21:10:33.421+0000] {taskinstance.py:2613} INFO - Dependencies all met for dep_context=requeueable deps ti=<TaskInstance: execute_entities.extract_and_load_omie_entities.extract_and_load_ListarMovimentos manual__2025-03-02T21:10:13.514914+00:00 [queued]>
[2025-03-02T21:10:33.422+0000] {taskinstance.py:2866} INFO - Starting attempt 1 of 4
[2025-03-02T21:10:33.440+0000] {taskinstance.py:2889} INFO - Executing <Task(PythonOperator): extract_and_load_omie_entities.extract_and_load_ListarMovimentos> on 2025-03-02 21:10:13.514914+00:00
[2025-03-02T21:10:33.446+0000] {warnings.py:112} WARNING - /home/***/.local/lib/python3.12/site-packages/***/task/task_runner/standard_task_runner.py:70: DeprecationWarning: This process (pid=115) is multi-threaded, use of fork() may lead to deadlocks in the child.
  pid = os.fork()

[2025-03-02T21:10:33.450+0000] {standard_task_runner.py:72} INFO - Started process 119 to run task
[2025-03-02T21:10:33.450+0000] {standard_task_runner.py:104} INFO - Running: ['***', 'tasks', 'run', 'execute_entities', 'extract_and_load_omie_entities.extract_and_load_ListarMovimentos', 'manual__2025-03-02T21:10:13.514914+00:00', '--job-id', '72', '--raw', '--subdir', 'DAGS_FOLDER/execute_entities.py', '--cfg-path', '/tmp/tmp4xehbgld']
[2025-03-02T21:10:33.453+0000] {standard_task_runner.py:105} INFO - Job 72: Subtask extract_and_load_omie_entities.extract_and_load_ListarMovimentos
[2025-03-02T21:10:33.511+0000] {task_command.py:467} INFO - Running <TaskInstance: execute_entities.extract_and_load_omie_entities.extract_and_load_ListarMovimentos manual__2025-03-02T21:10:13.514914+00:00 [running]> on host eba33f90d1de
[2025-03-02T21:10:33.688+0000] {taskinstance.py:3132} INFO - Exporting env vars: AIRFLOW_CTX_DAG_OWNER='***' AIRFLOW_CTX_DAG_ID='execute_entities' AIRFLOW_CTX_TASK_ID='extract_and_load_omie_entities.extract_and_load_ListarMovimentos' AIRFLOW_CTX_EXECUTION_DATE='2025-03-02T21:10:13.514914+00:00' AIRFLOW_CTX_TRY_NUMBER='1' AIRFLOW_CTX_DAG_RUN_ID='manual__2025-03-02T21:10:13.514914+00:00'
[2025-03-02T21:10:33.690+0000] {taskinstance.py:731} INFO - ::endgroup::
[2025-03-02T21:10:36.708+0000] {log.py:232} WARNING - 2025-03-02 21:10:36.708 | INFO     | src.controllers.paginations.paginations:per_page:91 - Page 1 fetched. Total of records: 34
[2025-03-02T21:10:38.735+0000] {log.py:232} WARNING - 2025-03-02 21:10:38.735 | ERROR    | src.db.database:save_into_db:110 - Error saving data into table mf: Using URI string without sqlalchemy installed.
[2025-03-02T21:10:39.590+0000] {log.py:232} WARNING - 2025-03-02 21:10:39.589 | INFO     | src.controllers.paginations.paginations:per_page:91 - Page 2 fetched. Total of records: 48
[2025-03-02T21:10:44.278+0000] {log.py:232} WARNING - 2025-03-02 21:10:44.278 | ERROR    | src.db.database:update_table_structure:83 - Error updating table mf: (psycopg2.errors.UndefinedTable) relation "mf" does not exist

[SQL: ALTER TABLE mf ADD COLUMN "detalhes.cCodCateg" TEXT;]
(Background on this error at: https://sqlalche.me/e/14/f405)
[2025-03-02T21:10:44.401+0000] {log.py:232} WARNING - 2025-03-02 21:10:44.401 | ERROR    | src.db.database:save_into_db:110 - Error saving data into table mf: Using URI string without sqlalchemy installed.
[2025-03-02T21:10:45.110+0000] {log.py:232} WARNING - 2025-03-02 21:10:45.110 | INFO     | src.controllers.paginations.paginations:per_page:91 - Page 3 fetched. Total of records: 67
[2025-03-02T21:10:48.649+0000] {log.py:232} WARNING - 2025-03-02 21:10:48.649 | ERROR    | src.db.database:update_table_structure:83 - Error updating table mf: (psycopg2.errors.UndefinedTable) relation "mf" does not exist

[SQL: ALTER TABLE mf ADD COLUMN "detalhes.cCPFCNPJCliente" TEXT;]
(Background on this error at: https://sqlalche.me/e/14/f405)
[2025-03-02T21:10:48.776+0000] {log.py:232} WARNING - 2025-03-02 21:10:48.775 | ERROR    | src.db.database:save_into_db:110 - Error saving data into table mf: Using URI string without sqlalchemy installed.
[2025-03-02T21:10:49.760+0000] {log.py:232} WARNING - 2025-03-02 21:10:49.760 | INFO     | src.controllers.paginations.paginations:per_page:91 - Page 4 fetched. Total of records: 76
[2025-03-02T21:10:53.321+0000] {log.py:232} WARNING - 2025-03-02 21:10:53.321 | ERROR    | src.db.database:update_table_structure:83 - Error updating table mf: (psycopg2.errors.UndefinedTable) relation "mf" does not exist

[SQL: ALTER TABLE mf ADD COLUMN "detalhes.cCPFCNPJCliente" TEXT;]
(Background on this error at: https://sqlalche.me/e/14/f405)
[2025-03-02T21:10:53.450+0000] {log.py:232} WARNING - 2025-03-02 21:10:53.450 | ERROR    | src.db.database:save_into_db:110 - Error saving data into table mf: Using URI string without sqlalchemy installed.
[2025-03-02T21:10:54.139+0000] {log.py:232} WARNING - 2025-03-02 21:10:54.139 | INFO     | src.controllers.paginations.paginations:per_page:91 - Page 5 fetched. Total of records: 84
[2025-03-02T21:10:58.642+0000] {log.py:232} WARNING - 2025-03-02 21:10:58.642 | ERROR    | src.db.database:update_table_structure:83 - Error updating table mf: (psycopg2.errors.UndefinedTable) relation "mf" does not exist

[SQL: ALTER TABLE mf ADD COLUMN "detalhes.cCPFCNPJCliente" TEXT;]
(Background on this error at: https://sqlalche.me/e/14/f405)
[2025-03-02T21:10:58.769+0000] {log.py:232} WARNING - 2025-03-02 21:10:58.769 | ERROR    | src.db.database:save_into_db:110 - Error saving data into table mf: Using URI string without sqlalchemy installed.
[2025-03-02T21:10:58.772+0000] {python.py:240} INFO - Done. Returned value was: None
[2025-03-02T21:10:59.159+0000] {taskinstance.py:340} INFO - ::group::Post task execution logs
[2025-03-02T21:10:59.160+0000] {taskinstance.py:352} INFO - Marking task as SUCCESS. dag_id=execute_entities, task_id=extract_and_load_omie_entities.extract_and_load_ListarMovimentos, run_id=manual__2025-03-02T21:10:13.514914+00:00, execution_date=20250302T211013, start_date=20250302T211033, end_date=20250302T211059
[2025-03-02T21:10:59.277+0000] {local_task_job_runner.py:266} INFO - Task exited with return code 0
[2025-03-02T21:10:59.360+0000] {taskinstance.py:3895} INFO - 1 downstream tasks scheduled from follow-on schedule check
[2025-03-02T21:10:59.363+0000] {local_task_job_runner.py:245} INFO - ::endgroup::
